<robot name="onbot">
<link name="base_link"></link>
<joint name="base_link_to_base" type="fixed">
<parent link="base_link"/>
<child link="link_0" />
<origin rpy="0.0 0 0" xyz="0 0 0"/>
</joint>
<link name="link_0">
<visual>
<origin xyz="-4.6030238945835243419e-05 1.5265566588595902431e-16 -5.1719199876371080293e-05" rpy="0 -0 0" />
<geometry>
<mesh filename="package://onbot_description/model/link_0.stl"/>
</geometry>
<material name="link_0_material">
<color rgba="0.61568627450980395466 0.81176470588235294379 0.92941176470588238168 1.0"/>
</material>
</visual>
<collision>
<origin xyz="-4.6030238945835243419e-05 1.5265566588595902431e-16 -5.1719199876371080293e-05" rpy="0 -0 0" />
<geometry>
<mesh filename="package://onbot_description/model/link_0.stl"/>
</geometry>
</collision>
<inertial>
<origin xyz="-4.6030238945840630548e-05 1.50370998007707436e-16 0.00875189381773204024" rpy="0 0 0"/>
<mass value="0.19748871252557395617" />
<inertia ixx="0.00023806805487244103465" ixy="0"  ixz="0" iyy="0.00023806805487244111596" iyz="0" izz="0.00036736927045971060242" />
</inertial>
</link>

<link name="link_1">
<visual>
<origin xyz="0 2.4492935982947009909e-18 0.050000000000000002776" rpy="3.141592653589793116 -0 0" />
<geometry>
<mesh filename="package://onbot_description/model/link_1.stl"/>
</geometry>
<material name="link_1_material">
<color rgba="0.64705882352941179736 0.64705882352941179736 0.64705882352941179736 1.0"/>
</material>
</visual>
<collision>
<origin xyz="0 2.4492935982947009909e-18 0.050000000000000002776" rpy="3.141592653589793116 -0 0" />
<geometry>
<mesh filename="package://onbot_description/model/link_1.stl"/>
</geometry>
</collision>
<inertial>
<origin xyz="-2.1009090720132303427e-07 0.018046899242789186252 -0.04459900315840159557" rpy="0 0 0"/>
<mass value="0.20422764659859179992" />
<inertia ixx="0.00040583180502166933202" ixy="-8.2126532819234253952e-10"  ixz="1.3097516849345761763e-10" iyy="0.00025569699180062245049" iyz="-5.1960999759273288282e-06" izz="0.00040933805553530343713" />
</inertial>
</link>

<link name="link_2">
<visual>
<origin xyz="3.4694469519536141888e-18 0.089999999999999996669 0.088499999999999995337" rpy="1.570796326794896558 -0 0" />
<geometry>
<mesh filename="package://onbot_description/model/link_2.stl"/>
</geometry>
<material name="link_2_material">
<color rgba="0.2313725490196078538 0.38039215686274507888 0.7058823529411765163 1.0"/>
</material>
</visual>
<collision>
<origin xyz="3.4694469519536141888e-18 0.089999999999999996669 0.088499999999999995337" rpy="1.570796326794896558 -0 0" />
<geometry>
<mesh filename="package://onbot_description/model/link_2.stl"/>
</geometry>
</collision>
<inertial>
<origin xyz="-1.5128118543499437814e-07 -0.012641799801596770303 -0.033435261764562726472" rpy="0 0 0"/>
<mass value="0.11247063896424530638" />
<inertia ixx="0.00012176106546512120027" ixy="-6.3409838943978570137e-10"  ixz="4.4734681123913029655e-09" iyy="8.7652394673544626116e-05" iyz="1.1712555094518884594e-06" izz="0.00012405909656661268342" />
</inertial>
</link>

<link name="link_3">
<visual>
<origin xyz="0 -0.11849999999999999423 0.14999999999999999445" rpy="3.141592653589793116 -0 0" />
<geometry>
<mesh filename="package://onbot_description/model/link_3.stl"/>
</geometry>
<material name="link_3_material">
<color rgba="0.91764705882352937127 0.91764705882352937127 0.91764705882352937127 1.0"/>
</material>
</visual>
<collision>
<origin xyz="0 -0.11849999999999999423 0.14999999999999999445" rpy="3.141592653589793116 -0 0" />
<geometry>
<mesh filename="package://onbot_description/model/link_3.stl"/>
</geometry>
</collision>
<inertial>
<origin xyz="0.0078337060796188819761 -1.0386783531879384412e-07 -0.10013861962485157142" rpy="0 0 0"/>
<mass value="0.22737840994406133266" />
<inertia ixx="0.00079860275000988908273" ixy="-1.6677542779044484445e-10"  ixz="0.00012519289428229732016" iyy="0.0008434141205222407461" iyz="-1.9913502200771837082e-09" izz="0.00019249795570076301803" />
</inertial>
</link>

<link name="link_4">
<visual>
<origin xyz="0.20262179871384716767 -0.11849999999999995259 0.28021418370089529182" rpy="3.141592653589793116 0.78539816339744883411 0" />
<geometry>
<mesh filename="package://onbot_description/model/link_4.stl"/>
</geometry>
<material name="link_4_material">
<color rgba="0.76862745098039220171 0.88627450980392152857 0.95294117647058818044 1.0"/>
</material>
</visual>
<collision>
<origin xyz="0.20262179871384716767 -0.11849999999999995259 0.28021418370089529182" rpy="3.141592653589793116 0.78539816339744883411 0" />
<geometry>
<mesh filename="package://onbot_description/model/link_4.stl"/>
</geometry>
</collision>
<inertial>
<origin xyz="2.4284498537086030012e-07 0.0082832269284789233899 -0.022081712352676030608" rpy="0 0 0"/>
<mass value="0.048256844879494255329" />
<inertia ixx="2.2358212256931444086e-05" ixy="-3.7883120505678243642e-12"  ixz="-1.1603773543795602136e-10" iyy="1.5613914290225994826e-05" iyz="-1.5948861987615502584e-07" izz="2.2572518701391077074e-05" />
</inertial>
</link>

<link name="link_5">
<visual>
<origin xyz="-0.068962223089810953391 0.3555068611989034566 0.15849999999999994649" rpy="1.570796326794896558 -0 0" />
<geometry>
<mesh filename="package://onbot_description/model/link_5.stl"/>
</geometry>
<material name="link_5_material">
<color rgba="0.97254901960784312376 0.52941176470588235947 0.0039215686274509803377 1.0"/>
</material>
</visual>
<collision>
<origin xyz="-0.068962223089810953391 0.3555068611989034566 0.15849999999999994649" rpy="1.570796326794896558 -0 0" />
<geometry>
<mesh filename="package://onbot_description/model/link_5.stl"/>
</geometry>
</collision>
<inertial>
<origin xyz="-0.0022489573708548982189 0.0022429133128372136241 -0.015487782949528905441" rpy="0 0 0"/>
<mass value="0.019619388673335114853" />
<inertia ixx="3.9829832114202757282e-06" ixy="-4.7305678667754595918e-08"  ixz="-4.0715333009412489415e-07" iyy="3.9834498983275300703e-06" iyz="4.079331029878774833e-07" izz="4.3358514980470292728e-06" />
</inertial>
</link>

<link name="end_effector">
<visual>
<origin xyz="0.20262179871384719543 0.17825897037982946225 -0.28021418370089534733" rpy="0 -0.78539816339744883411 0" />
<geometry>
<mesh filename="package://onbot_description/model/end_effector.stl"/>
</geometry>
<material name="end_effector_material">
<color rgba="0.49803921568627451677 0.49803921568627451677 0.49803921568627451677 1.0"/>
</material>
</visual>
<collision>
<origin xyz="0.20262179871384719543 0.17825897037982946225 -0.28021418370089534733" rpy="0 -0.78539816339744883411 0" />
<geometry>
<mesh filename="package://onbot_description/model/end_effector.stl"/>
</geometry>
</collision>
<inertial>
<origin xyz="5.5511151231257827021e-17 8.3266726846886752858e-17 -0.013935997588811366299" rpy="0 0 0"/>
<mass value="0.011726452949906113893" />
<inertia ixx="1.6310702112671920742e-06" ixy="0"  ixz="-1.2892725899987697217e-21" iyy="1.6310702112671910154e-06" iyz="0" izz="9.6128966498054122092e-07" />
</inertial>
</link>

<joint name="Joint_6" type="revolute">
<origin xyz="-0.014100633793567837748 0.014085751536034640807 -0.019686827757306402109" rpy="1.570796326794896558 -0 0.78539816339744883411" />
<parent link="link_5" />
<child link="end_effector" />
<axis xyz="0 0 1"/>
<limit effort="1" velocity="20" lower="-1.570796326794896558" upper="1.570796326794896558"/>
<joint_properties friction="0.0"/>
</joint>

<joint name="Joint_5" type="revolute">
<origin xyz="-5.5511151231257827021e-17 0.040000000000000104916 -0.020000000000000128786" rpy="1.570796326794896558 0.78539816339744883411 0" />
<parent link="link_4" />
<child link="link_5" />
<axis xyz="0 0 1"/>
<limit effort="1" velocity="20" lower="-1.570796326794896558" upper="1.570796326794896558"/>
<joint_properties friction="0.0"/>
</joint>

<joint name="Joint_4" type="revolute">
<origin xyz="0.054866101592779180363 -1.3877787807814456755e-17 -0.19141659736633301336" rpy="0 -0.78539816339744883411 0" />
<parent link="link_3" />
<child link="link_4" />
<axis xyz="0 0 1"/>
<limit effort="1" velocity="20" lower="-1.570796326794896558" upper="1.570796326794896558"/>
<joint_properties friction="0.0"/>
</joint>

<joint name="Joint_3" type="revolute">
<origin xyz="-1.2962992224779812389e-17 -0.060000000000000081046 -0.029999999999999985012" rpy="-1.570796326794896558 -0 0" />
<parent link="link_2" />
<child link="link_3" />
<axis xyz="0 0 1"/>
<limit effort="1" velocity="20" lower="-1.570796326794896558" upper="1.570796326794896558"/>
<joint_properties friction="0.0"/>
</joint>

<joint name="Joint_2" type="revolute">
<origin xyz="-3.4694469519536141888e-18 0.088499999999999995337 -0.039999999999999993894" rpy="1.570796326794896558 -0 0" />
<parent link="link_1" />
<child link="link_2" />
<axis xyz="0 0 1"/>
<limit effort="1" velocity="20" lower="-1.570796326794896558" upper="1.570796326794896558"/>
<joint_properties friction="0.0"/>
</joint>

<joint name="Joint_1" type="revolute">
<origin xyz="-4.6030238945835243419e-05 1.551049594842537253e-16 0.049948280800123631695" rpy="3.141592653589793116 -0 0" />
<parent link="link_0" />
<child link="link_1" />
<axis xyz="0 0 1"/>
<limit effort="1" velocity="20" lower="-1.570796326794896558" upper="1.570796326794896558"/>
<joint_properties friction="0.0"/>
</joint>

<link name="world"/>

<joint name="virtual_joint" type="fixed">
<parent link="world"/>
<child link="base_link"/>
<origin xyz= "0 0 -0.05" rpy = "0 0 0"/>  
</joint>





<!-- 
        ############################### the following is the additional code #########################
-->

<!-- 
<transmission name="transmission_1">
        <plugin>transmission_interface/SimpleTransmission</plugin>
        <actuator name="motor_1" role="actuatorone"/>
        <joint name="joint_1" role="jointone">
                <mechanical_reduction>1.0</mechanical_reduction>
        </joint>
</transmission>

<transmission name="transmission_2">
        <plugin>transmission_interface/SimpleTransmission</plugin>
        <actuator name="motor_2" role="actuatorone"/>
        <joint name="joint_2" role="jointone">
                <mechanical_reduction>1.0</mechanical_reduction>
        </joint>
</transmission>

<transmission name="transmission_3">
        <plugin>transmission_interface/SimpleTransmission</plugin>
        <actuator name="motor_3" role="actuatorone"/>
        <joint name="joint_3" role="jointone">
                <mechanical_reduction>1.0</mechanical_reduction>
        </joint>
</transmission>

<transmission name="transmission_4">
        <plugin>transmission_interface/SimpleTransmission</plugin>
        <actuator name="motor_4" role="actuatorone"/>
        <joint name="joint_4" role="jointone">
                <mechanical_reduction>1.0</mechanical_reduction>
        </joint>
</transmission>

<transmission name="transmission_5">
        <plugin>transmission_interface/SimpleTransmission</plugin>
        <actuator name="motor_5" role="actuatorone"/>
        <joint name="joint_5" role="jointone">
                <mechanical_reduction>1.0</mechanical_reduction>
        </joint>
</transmission>

<transmission name="transmission_6">
        <plugin>transmission_interface/SimpleTransmission</plugin>
        <actuator name="motor_6" role="actuatorone"/>
        <joint name="joint_6" role="jointone">
                <mechanical_reduction>1.0</mechanical_reduction>
        </joint>
</transmission> -->

<!-- <gazebo>
        <plugin filename="ign_ros2_control-system" name="ign_ros2_control::IgnitionROS2ControlPlugin">
                <robot_param>robot_description</robot_param>
                <robot_param_node>robot_state_publisher</robot_param_node>
                <parameters>$(find onbot_controller)/config/onbot_controller.yaml</parameters>
        </plugin>
</gazebo> -->

<gazebo>
        <plugin filename="ignition-gazebo-joint-position-controller-system" name="ignition::gazebo::systems::JointPositionController">
            <joint_name>Joint_1</joint_name>
        </plugin>    
</gazebo> 
<gazebo>
        <plugin filename="ignition-gazebo-joint-position-controller-system" name="ignition::gazebo::systems::JointPositionController">
            <joint_name>Joint_2</joint_name>
        </plugin>    
</gazebo> 
<gazebo>
        <plugin filename="ignition-gazebo-joint-position-controller-system" name="ignition::gazebo::systems::JointPositionController">
            <joint_name>Joint_3</joint_name>
        </plugin>    
</gazebo> 
<gazebo>
        <plugin filename="ignition-gazebo-joint-position-controller-system" name="ignition::gazebo::systems::JointPositionController">
            <joint_name>Joint_4</joint_name>
        </plugin>    
</gazebo> 
<gazebo>
        <plugin filename="ignition-gazebo-joint-position-controller-system" name="ignition::gazebo::systems::JointPositionController">
            <joint_name>Joint_5</joint_name>
        </plugin>    
</gazebo> 
<gazebo>
        <plugin filename="ignition-gazebo-joint-position-controller-system" name="ignition::gazebo::systems::JointPositionController">
            <joint_name>Joint_6</joint_name>
        </plugin>    
</gazebo> 


<!-- <ros2_control>
        <hardware>
                <plugin>ign_ros2_control/IgnitionSystem</plugin>
        </hardware>
        <joint name="joint_1">
                <command_interface name="position">
                        <param name="min">-1.570796326794896558</param>
                        <param name="max">1.570796326794896558</param>
                </command_interface>
                <state_interface name="position"/>
        </joint> 
        <joint name="joint_2">
                <command_interface name="position">
                        <param name="min">-1.570796326794896558</param>
                        <param name="max">1.570796326794896558</param>
                </command_interface>
                <state_interface name="position"/>
        </joint> 
        <joint name="joint_3">
                <command_interface name="position">
                        <param name="min">-1.570796326794896558</param>
                        <param name="max">1.570796326794896558</param>
                </command_interface>
                <state_interface name="position"/>
        </joint> 
        <joint name="joint_4">
                <command_interface name="position">
                        <param name="min">-1.570796326794896558</param>
                        <param name="max">1.570796326794896558</param>
                </command_interface>
                <state_interface name="position"/>
        </joint> 
        <joint name="joint_5">
                <command_interface name="position">
                        <param name="min">-1.570796326794896558</param>
                        <param name="max">1.570796326794896558</param>
                </command_interface>
                <state_interface name="position"/>
        </joint> 
        <joint name="joint_6">
                <command_interface name="position">
                        <param name="min">-1.570796326794896558</param>
                        <param name="max">1.570796326794896558</param>
                </command_interface>
                <state_interface name="position"/>
        </joint>   
</ros2_control> -->

</robot>
